% ===================================================================
% TEST 48: ISO Exception Handling System (catch/3, throw/1)
% ===================================================================
% Tests the complete ISO Prolog exception handling system implemented in Phase 2

% Test 1: Basic throw/catch mechanism
test_basic_throw_catch :-
    write('Testing basic throw/catch:'), nl,
    
    % Test 1.1: Simple throw and catch
    catch(throw(my_error), my_error, write('PASS: Caught my_error')), nl,
    
    % Test 1.2: Throw with compound term
    catch(throw(error(my_type, context)), error(Type, _), 
          (write('PASS: Caught error type: '), write(Type))), nl,
    
    % Test 1.3: Uncaught exception should propagate
    catch(catch(throw(inner_error), outer_error, write('Should not match')),
          inner_error, write('PASS: Inner error propagated')), nl,
    
    write('Basic throw/catch completed'), nl.

% Test 2: Division by zero error handling  
test_division_by_zero :-
    write('Testing division by zero error handling:'), nl,
    
    % Test 2.1: Catch division by zero in arithmetic evaluation
    catch(X is 1 / 0, error(evaluation_error(zero_divisor), _), 
          write('PASS: Caught division by zero')), nl,
    
    % Test 2.2: Catch modulo by zero
    catch(X is 5 mod 0, error(evaluation_error(zero_divisor), _),
          write('PASS: Caught modulo by zero')), nl,
    
    % Test 2.3: Catch remainder by zero  
    catch(X is 7 rem 0, error(evaluation_error(zero_divisor), _),
          write('PASS: Caught remainder by zero')), nl,
    
    write('Division by zero testing completed'), nl.

% Test 3: Exception unification and pattern matching
test_exception_unification :-
    write('Testing exception unification:'), nl,
    
    % Test 3.1: Exact unification
    catch(throw(specific_error(data)), specific_error(X), 
          (write('PASS: Unified data = '), write(X))), nl,
    
    % Test 3.2: Partial unification with variables
    catch(throw(error(type_error(integer, abc), context)), 
          error(type_error(Type, Culprit), _),
          (write('PASS: Type='), write(Type), write(', Culprit='), write(Culprit))), nl,
    
    % Test 3.3: Non-matching exception
    Result = fail,
    catch((catch(throw(first_error), second_error, (Result = caught)), Result = not_caught),
          first_error, (Result = outer_caught)),
    (Result = outer_caught -> write('PASS: Exception propagated correctly') ; 
                             write('FAIL: Exception handling incorrect')), nl,
    
    write('Exception unification completed'), nl.

% Test 4: Exception handling in complex expressions
test_complex_exception_handling :-
    write('Testing complex exception handling:'), nl,
    
    % Test 4.1: Exception in nested arithmetic
    catch((X is 1 + (2 * (3 / 0))), error(evaluation_error(zero_divisor), _),
          write('PASS: Caught nested division by zero')), nl,
    
    % Test 4.2: Multiple catch levels
    catch(catch(throw(inner_exception), wrong_exception, fail),
          inner_exception, write('PASS: Multi-level catch works')), nl,
    
    % Test 4.3: Exception with recovery action
    catch(throw(recoverable_error), recoverable_error, 
          (write('PASS: Executing recovery - '), write('recovery successful'))), nl,
    
    write('Complex exception handling completed'), nl.

% Test 5: ISO standard error term structures
test_iso_error_terms :-
    write('Testing ISO standard error terms:'), nl,
    
    % Test 5.1: Test if we can catch standard error patterns
    % (These would be thrown by built-ins if they were fully ISO compliant)
    
    % Demonstrate the expected structure for various error types
    write('Expected ISO error term patterns:'), nl,
    write('- instantiation_error: error(instantiation_error, Context)'), nl,
    write('- type_error: error(type_error(ValidType, Culprit), Context)'), nl,
    write('- domain_error: error(domain_error(ValidDomain, Culprit), Context)'), nl,
    write('- evaluation_error: error(evaluation_error(Error), Context)'), nl,
    write('- existence_error: error(existence_error(ObjectType, Culprit), Context)'), nl,
    write('- permission_error: error(permission_error(Operation, PermType, Culprit), Context)'), nl,
    write('- representation_error: error(representation_error(Flag), Context)'), nl,
    write('- syntax_error: error(syntax_error(ImplDepAtom), Context)'), nl,
    
    write('ISO error term documentation completed'), nl.

% Test 6: Exception handling with cut  
test_exception_with_cut :-
    write('Testing exception handling with cut:'), nl,
    
    % Test 6.1: Cut should not affect exception propagation
    test_cut_exception_helper(Result),
    (Result = caught -> write('PASS: Cut does not block exceptions') ;
                       write('FAIL: Cut affected exception handling')), nl,
    
    write('Exception with cut completed'), nl.

test_cut_exception_helper(caught) :-
    catch((!, throw(cut_test_error)), cut_test_error, true).

% Test 7: Exception handling in findall and meta-predicates
test_exception_in_meta_predicates :-
    write('Testing exceptions in meta-predicates:'), nl,
    
    % Test 7.1: Exception in findall goal
    catch(findall(X, (member(X, [1,2,0]), Y is 1/X), Results),
          error(evaluation_error(zero_divisor), _),
          write('PASS: Exception in findall caught')), nl,
          
    % Test 7.2: Exception should not prevent other solutions in findall
    % (This tests that findall handles exceptions per solution)
    findall(Result, 
            catch((member(X, [1,2,0,3]), Result is 1/X), 
                  error(evaluation_error(zero_divisor), _), 
                  Result = error), 
            AllResults),
    write('Results with error handling: '), write(AllResults), nl,
    
    write('Meta-predicate exception testing completed'), nl.

% Test 8: Exception handling with backtracking
test_exception_backtracking :-
    write('Testing exceptions with backtracking:'), nl,
    
    % Test 8.1: Exception should stop backtracking in the protected goal
    catch(exception_backtrack_helper(X), test_exception, 
          (write('PASS: Caught exception, X = '), write(X))), nl,
    
    write('Exception backtracking testing completed'), nl.

exception_backtrack_helper(1) :- write('Solution 1'), nl.
exception_backtrack_helper(2) :- write('Solution 2'), nl, throw(test_exception).
exception_backtrack_helper(3) :- write('Solution 3'), nl.

% Test 9: Exception handling with variable bindings
test_exception_variable_bindings :-
    write('Testing exception handling with variable bindings:'), nl,
    
    % Test 9.1: Variables should be properly bound in exception handler
    catch(throw(binding_test(value123)), binding_test(X), 
          (write('PASS: Variable bound in handler: X = '), write(X))), nl,
    
    % Test 9.2: Bindings from failed goal should not persist
    X = unbound,
    catch((X = bound_in_goal, throw(reset_test)), reset_test, true),
    (var(X) -> write('PASS: Bindings reset after exception') ;
               write('FAIL: Bindings persisted: X = '), write(X)), nl,
    
    write('Exception variable binding testing completed'), nl.

% Test 10: Stress test with multiple nested exceptions
test_nested_exceptions :-
    write('Testing nested exception handling:'), nl,
    
    % Test 10.1: Triple nested catch
    catch(
        catch(
            catch(throw(inner_most), wrong1, fail),
            wrong2, fail),
        inner_most, write('PASS: Triple nested catch successful')), nl,
    
    % Test 10.2: Exception in exception handler
    catch(catch(throw(first), first, throw(second)), second,
          write('PASS: Exception in handler caught')), nl,
    
    write('Nested exception testing completed'), nl.

% Master test runner
run_exception_tests :-
    write('=== ISO EXCEPTION HANDLING TEST SUITE ==='), nl,
    write('Testing complete throw/catch exception system'), nl, nl,
    
    test_basic_throw_catch, nl,
    test_division_by_zero, nl,  
    test_exception_unification, nl,
    test_complex_exception_handling, nl,
    test_iso_error_terms, nl,
    test_exception_with_cut, nl,
    test_exception_in_meta_predicates, nl,
    test_exception_backtracking, nl,
    test_exception_variable_bindings, nl,
    test_nested_exceptions, nl,
    
    write('=== EXCEPTION HANDLING TEST COMPLETED ==='), nl,
    write('All exception handling functionality has been tested'), nl.

% Quick individual tests for debugging
quick_test_throw :- throw(test_error).
quick_test_catch :- catch(throw(quick_test), quick_test, write('Caught quick_test')), nl.
quick_test_division :- catch(X is 1/0, Error, (write('Division error: '), write(Error))), nl.